<mujoco model="xarm6">
  <compiler angle="radian" meshdir="assets/"/>

  <option integrator="implicitfast"/>  <!-- 仿真选项：使用implicitfast积分器 -->

  <default>  <!-- 默认属性定义部分 -->
    <default class="xarm6">  <!-- 定义xarm7类的默认属性 -->
      <geom type="mesh" material="white"/>  <!-- 几何体类型为网格，使用白色材质 -->
      <joint axis="0 0 1" armature="0.1" range="-6.28319 6.28319" frictionloss="1"/>  <!-- 关节属性：Z轴旋转，转子惯性0.1，旋转范围±2π，摩擦损失1 在下面没有定义的时候就用默认的-->
      <general biastype="affine" ctrlrange="-6.28319 6.28319"/>  <!-- 通用驱动器：仿射偏置类型，控制范围±2π -->
      <default class="size1">  <!-- 定义size1子类默认属性 -->
        <joint damping="10"/>  <!-- 关节阻尼为10 -->
        <general gainprm="1500" biasprm="0 -1500 -150" forcerange="-50 50"/>  <!-- 通用驱动器参数：增益1500，偏置参数0 -1500 -150，力范围±50 -->
      </default>
      <default class="size2">  <!-- 定义size2子类默认属性 -->
        <joint damping="5"/>  <!-- 关节阻尼为5 -->
        <general gainprm="1000" biasprm="0 -1000 -100" forcerange="-30 30"/>  <!-- 通用驱动器参数：增益1000，偏置参数0 -1000 -100，力范围±30 -->
      </default>
      <default class="size3">  <!-- 定义size3子类默认属性 -->
        <joint damping="2"/>  <!-- 关节阻尼为2 -->
        <general gainprm="800" biasprm="0 -800 -80" forcerange="-20 20"/>  <!-- 通用驱动器参数：增益800，偏置参数0 -800 -80，力范围±20 -->
      </default>
      <site size="0.001" rgba="1 0 0 1" group="4"/>  <!-- 空间点属性：尺寸0.001，红色，组别4 -->
    </default>
  </default>


  <asset>
    <mesh name="base" file="base.stl"/>
    <mesh name="base_vhacd" file="base_vhacd.obj"/>
    <mesh name="link1" file="link1.stl"/>
    <mesh name="link1_vhacd" file="link1_vhacd.obj"/>
    <mesh name="link2" file="link2.stl"/>
    <mesh name="link2_vhacd" file="link2_vhacd.obj"/>
    <mesh name="link3" file="link3.stl"/>
    <mesh name="link3_vhacd" file="link3_vhacd.obj"/>
    <mesh name="link4" file="link4.stl"/>
    <mesh name="link4_vhacd" file="link4_vhacd.obj"/>
    <mesh name="link5" file="link5.stl"/>
    <mesh name="link5_vhacd" file="link5_vhacd.obj"/>
    <mesh name="link6" file="link6.stl"/>
    <mesh name="link6_vhacd" file="link6_vhacd.obj"/>
  </asset>

  <worldbody>
    <body name="link_base" pos="0 0 0" >
      <inertial pos="0 0 0" 
          quat="0.998963 0 0 0.045497" 
          mass="2.7" 
          diaginertia="0.01 0.01 0.01"/>
      <geom name="link_base_visual" type="mesh" contype="0" conaffinity="0" group="1" density="0" rgba="0.28 0.52 0.92 1" mesh="base"/>
      <geom name="link_base_collision" type="mesh" rgba="0.28 0.52 0.92 1" mesh="base_vhacd"/>
      <body name="link1" pos="0 0 0.267">
        <inertial pos="-0.002 0.02692 -0.01332" quat="0.983139 0.180751 -0.00455228 0.0272976" mass="2.16" diaginertia="0.00539487 0.00519906 0.00281397"/>
        <joint name="joint1"  pos="0 0 0" axis="0 0 1" range="-6.28319 6.28319" actuatorfrcrange="-50 50" damping="1" frictionloss="1"/>
        <geom name="link1_visual" type="mesh" contype="0" conaffinity="0" group="1" density="0" rgba="0.85 0.19 0.21 1" mesh="link1"/>
        <geom name="link1_collision" type="mesh" rgba="0.85 0.19 0.21 1" mesh="link1_vhacd"/>
        <body name="link2" quat="0.707105 -0.707108 0 0">
          <inertial pos="0.03531 -0.21398 0.03386" quat="0.71118 0.614686 0.139936 -0.311132" mass="1.71" diaginertia="0.017867 0.017867 0.017867"/>
          <joint name="joint2" pos="0 0 0" axis="0 0 1" range="-2.059 2.0944" actuatorfrcrange="-50 50" damping="1" frictionloss="1"/>
          <geom name="link2_visual" type="mesh" contype="0" conaffinity="0" group="1" density="0" rgba="0.95 0.76 0.05 1" mesh="link2"/>
          <geom name="link2_collision" type="mesh" rgba="0.95 0.76 0.05 1" mesh="link2_vhacd"/>
          <body name="link3" pos="0.0535 -0.2845 0">
            <inertial pos="0.06781 0.10749 0.01457" quat="0.119516 0.409082 -0.734824 0.527638" mass="1.384" diaginertia="0.004543 0.004543 0.004543"/>
            <joint name="joint3" pos="0 0 0" axis="0 0 1" range="-3.927 0.19198" actuatorfrcrange="-32 32" damping="1" frictionloss="1"/>
            <geom name="link3_visual" type="mesh" contype="0" conaffinity="0" group="1" density="0" rgba="0.28 0.52 0.92 1" mesh="link3"/>
            <geom name="link3_collision" type="mesh" rgba="0.28 0.52 0.92 1" mesh="link3_vhacd"/>
            <body name="link4" pos="0.0775 0.3425 0" quat="0.707105 -0.707108 0 0">
              <inertial pos="-0.00021 0.02578 -0.02538" quat="0.994019 0.0752563 -0.00686804 0.0788347" mass="1.115" diaginertia="0.00440091 0.00406855 0.00103407"/>
              <joint name="joint4" pos="0 0 0" axis="0 0 1" range="-6.28319 6.28319" actuatorfrcrange="-32 32" damping="1" frictionloss="1"/>
              <geom name="link4_visual" type="mesh" contype="0" conaffinity="0" group="1" density="0" rgba="0.23 0.72 0.32 1" mesh="link4"/>
              <geom name="link4_collision" type="mesh" rgba="0.23 0.72 0.32 1" mesh="link4_vhacd"/>
              <body name="link5" quat="0.707105 0.707108 0 0">
                <inertial pos="0.05428 0.01781 0.00543" quat="-0.0766302 0.578118 -0.269638 0.766291" mass="1.275" diaginertia="0.00289757 0.0023276 0.000951789"/>
                <joint name="joint5" pos="0 0 0" axis="0 0 1" range="-1.69297 3.14159" actuatorfrcrange="-32 32" damping="1" frictionloss="1"/>
                <geom name="link5_visual" type="mesh" contype="0" conaffinity="0" group="1" density="0" rgba="0.85 0.19 0.21 1" mesh="link5"/>
                <geom name="link5_collision" type="mesh" rgba="0.85 0.19 0.21 1" mesh="link5_vhacd"/>
                <body name="link6" pos="0.076 0.097 0" quat="0.707105 -0.707108 0 0">
                  <inertial pos="0 0.00064 -0.00952" quat="0 0.707107 0 0.707107" mass="0.1096" diaginertia="7.9715e-05 4.8111e-05 4.5293e-05"/>
                  <joint name="joint6" pos="0 0 0" axis="0 0 1" range="-6.28319 6.28319" actuatorfrcrange="-20 20" damping="1" frictionloss="1"/>
                  <geom name="link6_visual" type="mesh" contype="0" conaffinity="0" group="1" density="0" rgba="0.753 0.753 0.753 1" mesh="link6"/>
                  <geom name="link6_collision" type="mesh" rgba="0.753 0.753 0.753 1" mesh="link6_vhacd"/>
                </body>
                <site name="ee_site" pos="0 0 0.1" />
              </body>
            </body>
          </body>
        </body>
      </body>
      <site name="base_link_site" pos="0 0 0" quat="1 0 0 0" />
    </body>
  </worldbody>
  <!-- motor型执行器：直接施加力矩/力，没有内置控制回路。
  使用此类执行器时，用户需要自行计算并施加控制力矩来维持机械臂姿态，否则会因重力作用而下坠。 -->
  <!-- <actuator> 
    <motor name="joint1_motor" joint="joint1" gear="1"/>
    <motor name="joint2_motor" joint="joint2" gear="1"/>
    <motor name="joint3_motor" joint="joint3" gear="1"/>
    <motor name="joint4_motor" joint="joint4" gear="1"/>
    <motor name="joint5_motor" joint="joint5" gear="1"/>
    <motor name="joint6_motor" joint="joint6" gear="1"/>
  </actuator> -->

  <actuator>  <!-- 驱动器定义部分 -->
    <general name="act1" joint="joint1" class="size1"/>  <!-- 通用驱动器：名称act1，驱动joint1，使用size1类属性 -->
    <general name="act2" joint="joint2" class="size1" ctrlrange="-2.059 2.0944"/>  <!-- 通用驱动器：名称act2，驱动joint2，使用size1类属性，控制范围-2.059到2.0944 -->
    <general name="act3" joint="joint3" class="size2" ctrlrange="-3.927 0.19198"/>  <!-- 通用驱动器：名称act4，驱动joint4，使用size2类属性，控制范围-0.19198到3.927 -->
    <general name="act4" joint="joint4" class="size2"/>  <!-- 通用驱动器：名称act5，驱动joint5，使用size2类属性 -->
    <general name="act5" joint="joint5" class="size3" ctrlrange="-1.69297 3.14159"/>  <!-- 通用驱动器：名称act6，驱动joint6，使用size3类属性，控制范围-1.69297到3.14159 -->
    <general name="act6" joint="joint6" class="size3"/>  <!-- 通用驱动器：名称act7，驱动joint7，使用size3类属性 -->
  </actuator>

  <!-- <actuator> 
    <position name="joint1_position" joint="joint1" kp="1000" kv="100" ctrlrange="-6.28319 6.28319"/>
    <position name="joint2_position" joint="joint2" kp="1000" kv="100" ctrlrange="-2.059 2.0944"/>
    <position name="joint3_position" joint="joint3" kp="1000" kv="100" ctrlrange="-3.927 0.19198"/>
    <position name="joint4_position" joint="joint4" kp="1000" kv="100" ctrlrange="-6.28319 6.28319"/>
    <position name="joint5_position" joint="joint5" kp="1000" kv="100" ctrlrange="-1.69297 3.14159"/>
    <position name="joint6_position" joint="joint6" kp="1000" kv="100" ctrlrange="-6.28319 6.28319"/>
  </actuator> -->

  <contact>
    <exclude body1="link_base" body2="link1" />
    <exclude body1="link1" body2="link2" />
    <exclude body1="link2" body2="link3" />
    <exclude body1="link3" body2="link4" />
    <exclude body1="link4" body2="link5" />
    <exclude body1="link5" body2="link6" />
  </contact>
  
  <!-- <option gravity="0 0 0"/> -->

  <keyframe>
    <key name="home" qpos="0 0 0 0 0 0 " />
  </keyframe>

  <sensor>
    <framepos name="base_link_site_pos" objtype="site" objname="base_link_site" />
    <framequat name="base_link_site_quat" objtype="site" objname="base_link_site" />
    <framelinvel name="base_link_site_linvel" objtype="site" objname="base_link_site" />
    <frameangvel name="base_link_site_angvel" objtype="site" objname="base_link_site" />
    <velocimeter name="base_link_site_vel" site="base_link_site" />
    <!-- 为末端执行器添加传感器 -->
    <framepos name="ee_site_pos" objtype="site" objname="ee_site" />
    <framelinvel name="ee_site_linvel" objtype="site" objname="ee_site" />
    <frameangvel name="ee_site_angvel" objtype="site" objname="ee_site" />
    <velocimeter name="ee_site_vel" site="ee_site" />
  </sensor>

</mujoco>
